<?xml version="1.0" encoding="UTF-8"?>
<!-- Generated by org.testng.reporters.JUnitReportReporter -->
<testsuite hostname="GOGU" failures="1" tests="3" name="ecommerce.Tests.ErrorValidationsTest" time="76.271" errors="0" timestamp="2022-12-15T17:48:17 CST" skipped="1">
  <testcase classname="ecommerce.Tests.ErrorValidationsTest" name="ProductErrorValidation" time="17.197">
    <failure message="expected [true] but found [false]" type="java.lang.AssertionError">
      <![CDATA[java.lang.AssertionError: expected [true] but found [false]
at org.testng.Assert.fail(Assert.java:110)
at org.testng.Assert.failNotEquals(Assert.java:1413)
at org.testng.Assert.assertTrue(Assert.java:56)
at org.testng.Assert.assertTrue(Assert.java:66)
at ecommerce.Tests.ErrorValidationsTest.ProductErrorValidation(ErrorValidationsTest.java:40)
at java.base/jdk.internal.reflect.NativeMethodAccessorImpl.invoke0(Native Method)
at java.base/jdk.internal.reflect.NativeMethodAccessorImpl.invoke(NativeMethodAccessorImpl.java:77)
at java.base/jdk.internal.reflect.DelegatingMethodAccessorImpl.invoke(DelegatingMethodAccessorImpl.java:43)
at java.base/java.lang.reflect.Method.invoke(Method.java:568)
at org.testng.internal.invokers.MethodInvocationHelper.invokeMethod(MethodInvocationHelper.java:139)
at org.testng.internal.invokers.TestInvoker.invokeMethod(TestInvoker.java:677)
at org.testng.internal.invokers.TestInvoker.retryFailed(TestInvoker.java:263)
at org.testng.internal.invokers.MethodRunner.runInSequence(MethodRunner.java:62)
at org.testng.internal.invokers.TestInvoker$MethodInvocationAgent.invoke(TestInvoker.java:969)
at org.testng.internal.invokers.TestInvoker.invokeTestMethods(TestInvoker.java:194)
at org.testng.internal.invokers.TestMethodWorker.invokeTestMethods(TestMethodWorker.java:148)
at org.testng.internal.invokers.TestMethodWorker.run(TestMethodWorker.java:128)
at java.base/java.util.ArrayList.forEach(ArrayList.java:1511)
at org.testng.TestRunner.privateRun(TestRunner.java:829)
at org.testng.TestRunner.run(TestRunner.java:602)
at org.testng.SuiteRunner.runTest(SuiteRunner.java:437)
at org.testng.SuiteRunner$SuiteWorker.run(SuiteRunner.java:475)
at org.testng.internal.thread.ThreadUtil.lambda$execute$0(ThreadUtil.java:58)
at java.base/java.util.concurrent.FutureTask.run(FutureTask.java:264)
at java.base/java.util.concurrent.ThreadPoolExecutor.runWorker(ThreadPoolExecutor.java:1136)
at java.base/java.util.concurrent.ThreadPoolExecutor$Worker.run(ThreadPoolExecutor.java:635)
at java.base/java.lang.Thread.run(Thread.java:833)
]]>
    </failure>
  </testcase> <!-- ProductErrorValidation -->
  <system-out/>
  <testcase classname="ecommerce.Tests.ErrorValidationsTest" name="LoginErrorValidation" time="23.147"/>
  <system-out/>
  <testcase classname="ecommerce.Tests.ErrorValidationsTest" name="ProductErrorValidation" time="35.927">
    <skipped/>
  </testcase> <!-- ProductErrorValidation -->
  <system-out/>
</testsuite> <!-- ecommerce.Tests.ErrorValidationsTest -->
